2023-03-13 04:26:29,220 [INFO   ] [APP] allin50orderfillLiq2 started with arguments={rtg.py, run, allin50orderfillLiq2.py, allin50DEBUG2.py, WLiq.py, FastM2.py, WLowBuy.py, WLowBuy2.py, auto.py}
2023-03-13 04:26:29,220 [INFO   ] [APP] configuration={"Execution":{"Host":"127.0.0.1","Port":12345},"Information":{"Type":"mmap","Name":"info.dat"},"TeamName":"allin50orderfillLiq2","Secret":"secret"}
2023-03-13 04:26:29,220 [INFO   ] [CONNECTION] fd=740 connection established: peer=127.0.0.1:12345
2023-03-13 07:10:45,837 [INFO   ] [APP] allin50orderfillLiq2 started with arguments={rtg.py, run, autoBeta.py, allin50DEBUG2.py, FastM2.py, WLiq.py, WLowBuy.py, WLowBuy2.py, allin50orderfillLiq2.py}
2023-03-13 07:10:45,837 [INFO   ] [APP] configuration={"Execution":{"Host":"127.0.0.1","Port":12345},"Information":{"Type":"mmap","Name":"info.dat"},"TeamName":"allin50orderfillLiq2","Secret":"secret"}
2023-03-13 07:10:45,837 [INFO   ] [CONNECTION] fd=952 connection established: peer=127.0.0.1:12345
2023-03-13 07:10:45,837 [ERROR  ] [RECEIVER] connection lost:
Traceback (most recent call last):
  File "C:\Users\25910\OneDrive\\u684c\u9762\Math IC\Github\RTGSiuuuu\RTG\ready_trader_go\pubsub.py", line 136, in _subscribe_worker
    protocol.datagram_received(buffer[start:start + length], from_addr)
  File "C:\Users\25910\OneDrive\\u684c\u9762\Math IC\Github\RTGSiuuuu\RTG\ready_trader_go\messages.py", line 212, in datagram_received
    self.on_datagram(typ, data, HEADER_SIZE, length)
  File "C:\Users\25910\OneDrive\\u684c\u9762\Math IC\Github\RTGSiuuuu\RTG\ready_trader_go\base_auto_trader.py", line 69, in on_datagram
    self.on_order_book_update_message(inst, seq, *BOOK_PART.iter_unpack(data[ORDER_BOOK_HEADER_SIZE:]))
  File "C:\Users\25910\OneDrive\\u684c\u9762\Math IC\Github\RTGSiuuuu\RTG\allin50orderfillLiq2.py", line 147, in on_order_book_update_message
    self.new_bid_price = self.bid_prices[0][0] -200  if self.bid_prices[0][0] != 0 else 0
TypeError: unsupported operand type(s) for -: 'NoneType' and 'int'
2023-03-13 07:10:45,837 [INFO   ] [APP] closing event loop
2023-03-13 07:10:45,837 [INFO   ] [CONNECTION] fd=952 connection lost
2023-03-13 07:10:45,837 [ERROR  ] [asyncio] Exception in callback _SelectorSocketTransport._call_connection_lost(None)
handle: <Handle _SelectorSocketTransport._call_connection_lost(None)>
Traceback (most recent call last):
  File "C:\Program Files\WindowsApps\PythonSoftwareFoundation.Python.3.10_3.10.2800.0_x64__qbz5n2kfra8p0\lib\asyncio\events.py", line 80, in _run
    self._context.run(self._callback, *self._args)
  File "C:\Program Files\WindowsApps\PythonSoftwareFoundation.Python.3.10_3.10.2800.0_x64__qbz5n2kfra8p0\lib\asyncio\selector_events.py", line 984, in _call_connection_lost
    super()._call_connection_lost(exc)
  File "C:\Program Files\WindowsApps\PythonSoftwareFoundation.Python.3.10_3.10.2800.0_x64__qbz5n2kfra8p0\lib\asyncio\selector_events.py", line 742, in _call_connection_lost
    self._protocol.connection_lost(exc)
  File "C:\Users\25910\OneDrive\\u684c\u9762\Math IC\Github\RTGSiuuuu\RTG\ready_trader_go\base_auto_trader.py", line 59, in connection_lost
    Subscription.close(self)
  File "C:\Users\25910\OneDrive\\u684c\u9762\Math IC\Github\RTGSiuuuu\RTG\ready_trader_go\messages.py", line 186, in close
    self._receiver_transport.close()
AttributeError: 'NoneType' object has no attribute 'close'
